<mujoco model="RightArm">
  <compiler angle="radian" meshdir="assets" autolimits="true"/>

  <option integrator="implicitfast" cone="elliptic" impratio="10"/>

  <default>
    <default class="right_arm">
      <material specular="0.5" shininess="0.25"/>
      <joint axis="0 1 0" range="-6.28319 6.28319" armature="0.1"/>
      <general gaintype="fixed" biastype="affine" ctrlrange="-6.2831 6.2831" gainprm="2000" biasprm="0 -2000 -400"
        forcerange="-150 150"/>

      <default class="shoulder_pan">
        <joint range="-3.1415 3.1415"/>
        <general ctrlrange="-3.1415 3.1415"/>
      </default>

      <default class="shoulder_lift">
        <joint range="-3.3 3"/>
        <general ctrlrange="-3.3 3"/>
      </default>

      <default class="shoulder_roll">
        <joint range="-3 3"/>
        <general ctrlrange="-3 3"/>
      </default>

      <default class="elbow_j">
        <joint range="0 3"/>
        <general ctrlrange="0 3"/>
      </default>

      <default class="visual">
        <geom type="mesh" contype="0" conaffinity="0" group="2"/>
      </default>

      <default class="collision">
        <geom type="capsule" group="3"/>
      </default>
      <site size="0.001" rgba="0.5 0.5 0.5 0.3" group="4"/>

    </default>

    <default class="right_hand">
      <mesh scale="0.001 0.001 0.001"/>
      <joint axis="1 0 0" damping="0.05" armature="0.0002" frictionloss="0.01"/>
      <position forcerange="-1 1"/>

      <default class="wrist">
        <joint damping="0.5"/>
        <default class="wrist_y">
          <joint axis="0 1 0" range="-0.523599 0.174533"/>
          <position kp="10" ctrlrange="-0.523599 0.174533" forcerange="-10 10"/>
        </default>
        <default class="wrist_x">
          <joint range="-0.698132 0.488692"/>
          <position kp="8" ctrlrange="-0.698132 0.488692" forcerange="-5 5"/>
        </default>
        <default class="wrist_z">
          <joint range="-1.5708 1.5708"/>
          <position kp="5" ctrlrange="-1.5708 1.5708" forcerange="-5 5"/>
        </default>
      </default>

      <default class="thumb">
        <default class="thbase">
          <joint axis="0 0 -1" range="-1.0472 1.0472"/>
          <position kp="0.4" ctrlrange="-1.0472 1.0472" forcerange="-3 3"/>
        </default>
        <default class="thproximal">
          <joint range="0 1.22173"/>
          <position ctrlrange="0 1.22173" forcerange="-2 2"/>
        </default>
        <default class="thhub">
          <joint range="-0.20944 0.20944"/>
          <position kp="0.5" ctrlrange="-0.20944 0.20944"/>
        </default>
        <default class="thmiddle">
          <joint axis="0 -1 0" range="-0.698132 0.698132"/>
          <position kp="1.5" ctrlrange="-0.698132 0.698132"/>
        </default>
        <default class="thdistal">
          <joint range="-0.261799 1.5708"/>
          <position ctrlrange="-0.261799 1.5708"/>
        </default>
      </default>

      <default class="metacarpal">
        <joint axis="0.573576 0 0.819152" range="0 0.785398"/>
        <position ctrlrange="0 0.785398"/>
      </default>
      <default class="knuckle">
        <joint axis="0 -1 0" range="-0.349066 0.349066"/>
        <position ctrlrange="-0.349066 0.349066"/>
      </default>
      <default class="proximal">
        <joint range="-0.261799 1.5708"/>
        <position ctrlrange="-0.261799 1.5708"/>
      </default>
      <default class="middle_distal">
        <joint range="0 1.5708"/>
        <position kp="0.5" ctrlrange="0 3.1415"/>
      </default>

      <default class="plastic">
        <geom solimp="0.5 0.99 0.0001" solref="0.005 1"/>
        <default class="plastic_visual">
          <geom type="mesh" material="gray" contype="0" conaffinity="0" group="2"/>
        </default>
        <default class="plastic_collision">
          <geom group="3"/>
        </default>
      </default>
      
      <default class="right_hand_touch">
        <site rgba="0 0 0 0"/>
      </default>

      <default class="site_grasp">
        <site group="4" rgba="0 0 0 0" size="0.003" type="sphere" pos="0 -0.005 0.02"/>
      </default>
    </default>

  </default>

  <asset>
    <material class="right_arm" name="black" rgba="0.033 0.033 0.033 1"/>
    <material class="right_arm" name="arm_gray" rgba="0.6 0.6 0.6 1"/>

    <material name="gray" specular="0.0" shininess="0.25" rgba="0.7 0.7 0.7 1"/>
    <material name="metallic" specular="0" shininess="0.25" rgba="0.9 0.9 0.9 1"/>

    <mesh class="right_hand" file="wrist.obj"/>
    <mesh class="right_hand" file="palm.obj"/>
    <mesh class="right_hand" file="f_knuckle.obj"/>
    <mesh class="right_hand" file="f_proximal.obj"/>
    <mesh class="right_hand" file="f_middle.obj"/>
    <mesh class="right_hand" file="f_distal_pst.obj"/>
    <mesh class="right_hand" file="lf_metacarpal.obj"/>
    <mesh class="right_hand" file="th_proximal.obj"/>
    <mesh class="right_hand" file="th_middle.obj"/>
    <mesh class="right_hand" file="th_distal_pst.obj"/>

  </asset>

  <worldbody>
    <light name="spotlight" mode="fixed" pos="0 0.5 1"/>
    <body name="base" quat="0.7071 0 0.7071 0" pos="0.2 0 0" childclass="right_arm">
      <inertial mass="2.0" pos="0 0 0" diaginertia="0.00443333156 0.00443333156 0.0072"/>
      <!-- <geom type="cylinder" size="0.015 0.02" pos="0 0 0.02" material="arm_gray" class="visual"/> -->
      <!-- <geom type="cylinder" size="0.015 0.008" pos="0 0 0.008" class="collision"/> -->

        <body name="shoulder_upper_arm" pos="0 0 0.05" quat="1 0 1 0">
          <inertial mass="5.0" pos="0 0 0.2" diaginertia="0.09 0.09 0.0023"/>
          <joint name="shoulder_pan_joint" class="shoulder_pan" axis="1 0 0"/>
          <joint name="shoulder_lift_joint" class="shoulder_lift" axis="0 1 0"/>
          <joint name="shoulder_roll_joint" class="shoulder_roll" axis="0 0 1"/>
          <geom type="capsule" size="0.03 0.2" pos="0 0 0.2" material="arm_gray" class="visual"/>
          <geom type="capsule" size="0.03 0.2" pos="0 0 0.2" class="collision" />
          
          <body name="elbow_forearm" pos="0 0 0.4" quat="0.7071 0 0 0.7071">
            <inertial mass="5.0" pos="0 0 0.2" diaginertia="0.09 0.09 0.0023"/>
            <joint name="elbow_joint" class="elbow_j"/>
            <geom type="cylinder" size="0.03 0.2" pos="0 0 0.2" material="arm_gray" class="visual"/>         
            <geom type="cylinder" size="0.03 0.2" pos="0 0 0.2" class="collision" />

            <body name="rh_wrist" pos="0 0 0.4" quat="1 0 0 0">
              <inertial mass="0.1" pos="0 0 0.029" quat="0.5 0.5 0.5 0.5" diaginertia="6.4e-05 4.38e-05 3.5e-05"/>
              <joint class="wrist_z" name="rh_WRJ0" axis="0 0 1"/>
              <joint class="wrist_y" name="rh_WRJ2"/>
              <geom class="plastic_visual" mesh="wrist" material="metallic"/>
              <geom size="0.0135 0.015" quat="0.499998 0.5 0.5 -0.500002" type="cylinder" class="plastic_collision"/>
              <geom size="0.011 0.005" pos="-0.026 0 0.034" quat="1 0 1 0" type="cylinder" class="plastic_collision"/>
              <geom size="0.011 0.005" pos="0.031 0 0.034" quat="1 0 1 0" type="cylinder" class="plastic_collision"/>
              <geom size="0.0135 0.009 0.005" pos="-0.021 0 0.011" quat="0.923879 0 0.382684 0" type="box"
                class="plastic_collision"/>
              <geom size="0.0135 0.009 0.005" pos="0.026 0 0.01" quat="0.923879 0 -0.382684 0" type="box"
                class="plastic_collision"/>
              <body name="rh_palm" pos="0 0 0.034">
                <inertial mass="0.3" pos="0 0 0.035" quat="1 0 0 1" diaginertia="0.0005287 0.0003581 0.000191"/>
                <joint class="wrist_x" name="rh_WRJ1"/>
                <site name="site_grasp_palm" class="site_grasp" pos="0 -0.01 0.05"/>
                <geom class="plastic_visual" mesh="palm"/>
                <geom size="0.031 0.0035 0.049" pos="0.011 0.0085 0.038" type="box" class="plastic_collision"/>
                <geom size="0.018 0.0085 0.049" pos="-0.002 -0.0035 0.038" type="box" class="plastic_collision"/>
                <geom size="0.013 0.0085 0.005" pos="0.029 -0.0035 0.082" type="box" class="plastic_collision"/>
                <geom size="0.013 0.007 0.009" pos="0.0265 -0.001 0.07" quat="0.987241 0.0990545 0.0124467 0.124052"
                  type="box" class="plastic_collision"/>
                <geom size="0.0105 0.0135 0.012" pos="0.0315 -0.0085 0.001" type="box" class="plastic_collision"/>
                <geom size="0.011 0.0025 0.015" pos="0.0125 -0.015 0.004" quat="0.971338 0 0 -0.237703" type="box"
                  class="plastic_collision"/>
                <geom size="0.009 0.012 0.002" pos="0.011 0 0.089" type="box" class="plastic_collision"/>
                <geom size="0.01 0.012 0.02" pos="-0.03 0 0.009" type="box" class="plastic_collision"/>
                <site class="right_hand_touch" name="rh_T_palm_b0" type="box" pos="-0.0325 -0.006 0.014" size="0.01 0.007 0.027" />
                <site class="right_hand_touch" name="rh_T_palm_bl" type="box" pos="-0.011 -0.006 0.006" size="0.011 0.007 0.019"/>
                <site class="right_hand_touch" name="rh_T_palm_bm" type="box" pos="0.0125 -0.016 0.004" size="0.011 0.0025 0.016" quat="0.971338 0 0 -0.237703"/>
                <site class="right_hand_touch" name="rh_T_palm_br" type="box" pos="0.033 -0.016 0" size="0.011 0.007 0.013"/>
                <site class="right_hand_touch" name="rh_T_palm_ml" type="box" pos="-0.011 -0.006 0.041" size="0.011 0.007 0.016"/>
                <site class="right_hand_touch" name="rh_T_palm_mm" type="box" pos="0.011 -0.006 0.041" size="0.011 0.007 0.016"/>
                <site class="right_hand_touch" name="rh_T_palm_fl" type="box" pos="-0.011 -0.006 0.073" size="0.011 0.007 0.016"/>
                <site class="right_hand_touch" name="rh_T_palm_fm" type="box" pos="0.011 -0.006 0.073" size="0.011 0.007 0.016"/>
                <site class="right_hand_touch" name="rh_T_palm_fr" type="box" pos="0.033 -0.006 0.073" size="0.011 0.007 0.016"/>

                <body name="rh_ffknuckle" pos="0.033 0 0.095">
                  <inertial mass="0.008" pos="0 0 0" quat="0.5 0.5 -0.5 0.5" diaginertia="3.2e-07 2.6e-07 2.6e-07"/>
                  <joint name="rh_FFJ4" class="knuckle"/>
                  <geom pos="0 0 0.0005" class="plastic_visual" mesh="f_knuckle" material="metallic"/>
                  <geom size="0.009 0.009" quat="1 0 1 0" type="cylinder" class="plastic_collision"/>
                  <body name="rh_ffproximal">
                    <inertial mass="0.03" pos="0 0 0.0225" quat="1 0 0 1" diaginertia="1e-05 9.8e-06 1.8e-06"/>
                    <joint name="rh_FFJ3" class="proximal"/>
                    <geom class="plastic_visual" mesh="f_proximal"/>
                    <geom size="0.009 0.02" pos="0 0 0.025" type="capsule" class="plastic_collision"/>
                    <site class="right_hand_touch" name="rh_T_ffproximal_front_left_bottom" type="box" pos="-0.005 -0.005 0.00625" size="0.005 0.005 0.01625" />
                    <site class="right_hand_touch" name="rh_T_ffproximal_front_right_bottom" type="box" pos="0.005 -0.005 0.00625" size="0.005 0.005 0.01625" />
                    <site class="right_hand_touch" name="rh_T_ffproximal_front_left_top" type="box" pos="-0.005 -0.005 0.03875" size="0.005 0.005 0.01625" />
                    <site class="right_hand_touch" name="rh_T_ffproximal_front_right_top" type="box" pos="0.005 -0.005 0.03875" size="0.005 0.005 0.01625" />
                    <site class="right_hand_touch" name="rh_T_ffproximal_back_left" type="box" pos="-0.005 0.005 0.0225" size="0.005 0.005 0.0325" />
                    <site class="right_hand_touch" name="rh_T_ffproximal_back_right" type="box" pos="0.005 0.005 0.0225" size="0.005 0.005 0.0325" />
                    <site class="right_hand_touch" name="rh_T_ffproximal_tip" type="sphere" pos="0 0 0.045" size="0.011" />

                    <body name="rh_ffmiddle" pos="0 0 0.045">
                      <inertial mass="0.017" pos="0 0 0.0125" quat="1 0 0 1" diaginertia="2.7e-06 2.6e-06 8.7e-07"/>
                      <joint name="rh_FFJ2" class="middle_distal"/>
                      <geom class="plastic_visual" mesh="f_middle"/>
                      <geom size="0.009 0.0125" pos="0 0 0.0125" type="capsule" class="plastic_collision"/>
                      <site class="right_hand_touch" name="rh_T_ffmiddle_front_left" type="box" pos="-0.00451 -0.00451 0.0125" size="0.00451 0.00451 0.02055" />
                      <site class="right_hand_touch" name="rh_T_ffmiddle_front_right" type="box" pos="0.00451 -0.00451 0.0125" size="0.00451 0.00451 0.02055" />
                      <site class="right_hand_touch" name="rh_T_ffmiddle_back_left" type="box" pos="-0.00451 0.00451 0.0125" size="0.00451 0.00451 0.02055" />
                      <site class="right_hand_touch" name="rh_T_ffmiddle_back_right" type="box" pos="0.00451 0.00451 0.0125" size="0.00451 0.00451 0.02055" />
                      <site class="right_hand_touch" name="rh_T_ffmiddle_tip" type="sphere" pos="0 0 0.025" size="0.009" />

                      <body name="rh_ffdistal" pos="0 0 0.025">
                        <inertial mass="0.013" pos="0 0 0.0130769" quat="1 0 0 1"
                          diaginertia="1.28092e-06 1.12092e-06 5.3e-07"/>
                        <joint name="rh_FFJ1" class="middle_distal"/>
                        <geom class="plastic_visual" mesh="f_distal_pst"/>
                        <geom class="plastic_collision" type="mesh" mesh="f_distal_pst"/>
                        <site class="right_hand_touch" name="rh_T_fftip_front_left" type="box" pos="-0.00451 -0.00451 0.012" size="0.00451 0.00451 0.01905" />
                        <site class="right_hand_touch" name="rh_T_fftip_front_right" type="box" pos="0.00451 -0.00451 0.012" size="0.00451 0.00451 0.01905" />
                        <site class="right_hand_touch" name="rh_T_fftip_back_left" type="box" pos="-0.00451 0.00451 0.012" size="0.00451 0.00451 0.01905" />
                        <site class="right_hand_touch" name="rh_T_fftip_back_right" type="box" pos="0.00451 0.00451 0.012" size="0.00451 0.00451 0.01905" />
                        <site class="right_hand_touch" name="rh_T_fftip_tip" type="sphere" pos="0 0 0.024" size="0.008" />
                        <site name="site_grasp_ff1" class="site_grasp"/>
                      </body>
                    </body>
                  </body>
                </body>
                <body name="rh_mfknuckle" pos="0.011 0 0.099">
                  <inertial mass="0.008" pos="0 0 0" quat="0.5 0.5 -0.5 0.5" diaginertia="3.2e-07 2.6e-07 2.6e-07"/>
                  <joint name="rh_MFJ4" class="knuckle"/>
                  <geom pos="0 0 0.0005" class="plastic_visual" mesh="f_knuckle" material="metallic"/>
                  <geom size="0.009 0.009" quat="1 0 1 0" type="cylinder" class="plastic_collision"/>
                  <body name="rh_mfproximal">
                    <inertial mass="0.03" pos="0 0 0.0225" quat="1 0 0 1" diaginertia="1e-05 9.8e-06 1.8e-06"/>
                    <joint name="rh_MFJ3" class="proximal"/>
                    <geom class="plastic_visual" mesh="f_proximal"/>
                    <geom size="0.009 0.02" pos="0 0 0.025" type="capsule" class="plastic_collision"/>
                    <site class="right_hand_touch" name="rh_T_mfproximal_front_left_bottom" type="box" pos="-0.005 -0.005 0.00625" size="0.005 0.005 0.01625" />
                    <site class="right_hand_touch" name="rh_T_mfproximal_front_right_bottom" type="box" pos="0.005 -0.005 0.00625" size="0.005 0.005 0.01625" />
                    <site class="right_hand_touch" name="rh_T_mfproximal_front_left_top" type="box" pos="-0.005 -0.005 0.03875" size="0.005 0.005 0.01625" />
                    <site class="right_hand_touch" name="rh_T_mfproximal_front_right_top" type="box" pos="0.005 -0.005 0.03875" size="0.005 0.005 0.01625" />
                    <site class="right_hand_touch" name="rh_T_mfproximal_back_left" type="box" pos="-0.005 0.005 0.0225" size="0.005 0.005 0.0325" />
                    <site class="right_hand_touch" name="rh_T_mfproximal_back_right" type="box" pos="0.005 0.005 0.0225" size="0.005 0.005 0.0325" />
                    <site class="right_hand_touch" name="rh_T_mfproximal_tip" type="sphere" pos="0 0 0.045" size="0.011" />

                    <body name="rh_mfmiddle" pos="0 0 0.045">
                      <inertial mass="0.017" pos="0 0 0.0125" quat="1 0 0 1" diaginertia="2.7e-06 2.6e-06 8.7e-07"/>
                      <joint name="rh_MFJ2" class="middle_distal"/>
                      <geom class="plastic_visual" mesh="f_middle"/>
                      <geom size="0.009 0.0125" pos="0 0 0.0125" type="capsule" class="plastic_collision"/>
                      <site class="right_hand_touch" name="rh_T_mfmiddle_front_left" type="box" pos="-0.00451 -0.00451 0.0125" size="0.00451 0.00451 0.02055" />
                      <site class="right_hand_touch" name="rh_T_mfmiddle_front_right" type="box" pos="0.00451 -0.00451 0.0125" size="0.00451 0.00451 0.02055" />
                      <site class="right_hand_touch" name="rh_T_mfmiddle_back_left" type="box" pos="-0.00451 0.00451 0.0125" size="0.00451 0.00451 0.02055" />
                      <site class="right_hand_touch" name="rh_T_mfmiddle_back_right" type="box" pos="0.00451 0.00451 0.0125" size="0.00451 0.00451 0.02055" />
                      <site class="right_hand_touch" name="rh_T_mfmiddle_tip" type="sphere" pos="0 0 0.025" size="0.009" />

                      <body name="rh_mfdistal" pos="0 0 0.025">
                        <inertial mass="0.013" pos="0 0 0.0130769" quat="1 0 0 1"
                          diaginertia="1.28092e-06 1.12092e-06 5.3e-07"/>
                        <joint name="rh_MFJ1" class="middle_distal"/>
                        <geom class="plastic_visual" mesh="f_distal_pst"/>
                        <geom class="plastic_collision" type="mesh" mesh="f_distal_pst"/>
                        <site name="finger_tip_middle" pos="0 0 0.03" quat="1 0 0 1"/> <!--type="sphere"-->
                        <site class="right_hand_touch" name="rh_T_mftip_front_left" type="box" pos="-0.00451 -0.00451 0.012" size="0.00451 0.00451 0.01905" />
                        <site class="right_hand_touch" name="rh_T_mftip_front_right" type="box" pos="0.00451 -0.00451 0.012" size="0.00451 0.00451 0.01905" />
                        <site class="right_hand_touch" name="rh_T_mftip_back_left" type="box" pos="-0.00451 0.00451 0.012" size="0.00451 0.00451 0.01905" />
                        <site class="right_hand_touch" name="rh_T_mftip_back_right" type="box" pos="0.00451 0.00451 0.012" size="0.00451 0.00451 0.01905" />
                        <site class="right_hand_touch" name="rh_T_mftip_tip" type="sphere" pos="0 0 0.024" size="0.008" />
                        <site name="site_grasp_mf1" class="site_grasp"/>

                      </body>
                    </body>
                  </body>
                </body>
                <body name="rh_rfknuckle" pos="-0.011 0 0.095">
                  <inertial mass="0.008" pos="0 0 0" quat="0.5 0.5 -0.5 0.5" diaginertia="3.2e-07 2.6e-07 2.6e-07"/>
                  <joint name="rh_RFJ4" class="knuckle" axis="0 1 0"/>
                  <geom pos="0 0 0.0005" class="plastic_visual" mesh="f_knuckle" material="metallic"/>
                  <geom size="0.009 0.009" quat="1 0 1 0" type="cylinder" class="plastic_collision"/>
                  <body name="rh_rfproximal">
                    <inertial mass="0.03" pos="0 0 0.0225" quat="1 0 0 1" diaginertia="1e-05 9.8e-06 1.8e-06"/>
                    <joint name="rh_RFJ3" class="proximal"/>
                    <geom class="plastic_visual" mesh="f_proximal"/>
                    <geom size="0.009 0.02" pos="0 0 0.025" type="capsule" class="plastic_collision"/>
                    <site class="right_hand_touch" name="rh_T_rfproximal_front_left_bottom" type="box" pos="-0.005 -0.005 0.00625" size="0.005 0.005 0.01625" />
                    <site class="right_hand_touch" name="rh_T_rfproximal_front_right_bottom" type="box" pos="0.005 -0.005 0.00625" size="0.005 0.005 0.01625" />
                    <site class="right_hand_touch" name="rh_T_rfproximal_front_left_top" type="box" pos="-0.005 -0.005 0.03875" size="0.005 0.005 0.01625" />
                    <site class="right_hand_touch" name="rh_T_rfproximal_front_right_top" type="box" pos="0.005 -0.005 0.03875" size="0.005 0.005 0.01625" />
                    <site class="right_hand_touch" name="rh_T_rfproximal_back_left" type="box" pos="-0.005 0.005 0.0225" size="0.005 0.005 0.0325" />
                    <site class="right_hand_touch" name="rh_T_rfproximal_back_right" type="box" pos="0.005 0.005 0.0225" size="0.005 0.005 0.0325" />
                    <site class="right_hand_touch" name="rh_T_rfproximal_tip" type="sphere" pos="0 0 0.045" size="0.011" />

                    <body name="rh_rfmiddle" pos="0 0 0.045">
                      <inertial mass="0.017" pos="0 0 0.0125" quat="1 0 0 1" diaginertia="2.7e-06 2.6e-06 8.7e-07"/>
                      <joint name="rh_RFJ2" class="middle_distal"/>
                      <geom class="plastic_visual" mesh="f_middle"/>
                      <geom size="0.009 0.0125" pos="0 0 0.0125" type="capsule" class="plastic_collision"/>
                      <site class="right_hand_touch" name="rh_T_rfmiddle_front_left" type="box" pos="-0.00451 -0.00451 0.0125" size="0.00451 0.00451 0.02055" />
                      <site class="right_hand_touch" name="rh_T_rfmiddle_front_right" type="box" pos="0.00451 -0.00451 0.0125" size="0.00451 0.00451 0.02055" />
                      <site class="right_hand_touch" name="rh_T_rfmiddle_back_left" type="box" pos="-0.00451 0.00451 0.0125" size="0.00451 0.00451 0.02055" />
                      <site class="right_hand_touch" name="rh_T_rfmiddle_back_right" type="box" pos="0.00451 0.00451 0.0125" size="0.00451 0.00451 0.02055" />
                      <site class="right_hand_touch" name="rh_T_rfmiddle_tip" type="sphere" pos="0 0 0.025" size="0.009" />

                      <body name="rh_rfdistal" pos="0 0 0.025">
                        <inertial mass="0.013" pos="0 0 0.0130769" quat="1 0 0 1"
                          diaginertia="1.28092e-06 1.12092e-06 5.3e-07"/>
                        <joint name="rh_RFJ1" class="middle_distal"/>
                        <geom class="plastic_visual" mesh="f_distal_pst"/>
                        <geom class="plastic_collision" type="mesh" mesh="f_distal_pst"/>
                        <site class="right_hand_touch" name="rh_T_rftip_front_left" type="box" pos="-0.00451 -0.00451 0.012" size="0.00451 0.00451 0.01905" />
                        <site class="right_hand_touch" name="rh_T_rftip_front_right" type="box" pos="0.00451 -0.00451 0.012" size="0.00451 0.00451 0.01905" />
                        <site class="right_hand_touch" name="rh_T_rftip_back_left" type="box" pos="-0.00451 0.00451 0.012" size="0.00451 0.00451 0.01905" />
                        <site class="right_hand_touch" name="rh_T_rftip_back_right" type="box" pos="0.00451 0.00451 0.012" size="0.00451 0.00451 0.01905" />
                        <site class="right_hand_touch" name="rh_T_rftip_tip" type="sphere" pos="0 0 0.024" size="0.008" />
                        <site name="site_grasp_rf1" class="site_grasp" />

                      </body>
                    </body>
                  </body>
                </body>
                <body name="rh_lfmetacarpal" pos="-0.033 0 0.02071">
                  <inertial mass="0.03" pos="0 0 0.04" quat="1 0 0 1" diaginertia="1.638e-05 1.45e-05 4.272e-06"/>
                  <joint name="rh_LFJ5" class="metacarpal"/>
                  <geom class="plastic_visual" mesh="lf_metacarpal"/>
                  <geom size="0.011 0.012 0.025" pos="0.002 0 0.033" type="box" class="plastic_collision"/>
                  <site class="right_hand_touch" name="rh_T_lfmetacarpal_front" type="box" pos="0.002 -0.006 0.033" size="0.012 0.007 0.026" />

                  <body name="rh_lfknuckle" pos="0 0 0.06579">
                    <inertial mass="0.008" pos="0 0 0" quat="0.5 0.5 -0.5 0.5" diaginertia="3.2e-07 2.6e-07 2.6e-07"/>
                    <joint name="rh_LFJ4" class="knuckle" axis="0 1 0"/>
                    <geom pos="0 0 0.0005" class="plastic_visual" mesh="f_knuckle" material="metallic"/>
                    <geom size="0.009 0.009" quat="1 0 1 0" type="cylinder" class="plastic_collision"/>
                    <body name="rh_lfproximal">
                      <inertial mass="0.03" pos="0 0 0.0225" quat="1 0 0 1" diaginertia="1e-05 9.8e-06 1.8e-06"/>
                      <joint name="rh_LFJ3" class="proximal"/>
                      <geom class="plastic_visual" mesh="f_proximal"/>
                      <geom size="0.009 0.02" pos="0 0 0.025" type="capsule" class="plastic_collision"/>
                      <site class="right_hand_touch" name="rh_T_lfproximal_front_left_bottom" type="box" pos="-0.005 -0.005 0.00625" size="0.005 0.005 0.01625" />
                      <site class="right_hand_touch" name="rh_T_lfproximal_front_right_bottom" type="box" pos="0.005 -0.005 0.00625" size="0.005 0.005 0.01625" />
                      <site class="right_hand_touch" name="rh_T_lfproximal_front_left_top" type="box" pos="-0.005 -0.005 0.03875" size="0.005 0.005 0.01625" />
                      <site class="right_hand_touch" name="rh_T_lfproximal_front_right_top" type="box" pos="0.005 -0.005 0.03875" size="0.005 0.005 0.01625" />
                      <site class="right_hand_touch" name="rh_T_lfproximal_back_left" type="box" pos="-0.005 0.005 0.0225" size="0.005 0.005 0.0325" />
                      <site class="right_hand_touch" name="rh_T_lfproximal_back_right" type="box" pos="0.005 0.005 0.0225" size="0.005 0.005 0.0325" />
                      <site class="right_hand_touch" name="rh_T_lfproximal_tip" type="sphere" pos="0 0 0.045" size="0.011" />

                      <body name="rh_lfmiddle" pos="0 0 0.045">
                        <inertial mass="0.017" pos="0 0 0.0125" quat="1 0 0 1" diaginertia="2.7e-06 2.6e-06 8.7e-07"/>
                        <joint name="rh_LFJ2" class="middle_distal"/>
                        <geom class="plastic_visual" mesh="f_middle"/>
                        <geom size="0.009 0.0125" pos="0 0 0.0125" type="capsule" class="plastic_collision"/>
                        <site class="right_hand_touch" name="rh_T_lfmiddle_front_left" type="box" pos="-0.00451 -0.00451 0.0125" size="0.00451 0.00451 0.02055" />
                        <site class="right_hand_touch" name="rh_T_lfmiddle_front_right" type="box" pos="0.00451 -0.00451 0.0125" size="0.00451 0.00451 0.02055" />
                        <site class="right_hand_touch" name="rh_T_lfmiddle_back_left" type="box" pos="-0.00451 0.00451 0.0125" size="0.00451 0.00451 0.02055" />
                        <site class="right_hand_touch" name="rh_T_lfmiddle_back_right" type="box" pos="0.00451 0.00451 0.0125" size="0.00451 0.00451 0.02055" />
                        <site class="right_hand_touch" name="rh_T_lfmiddle_tip" type="sphere" pos="0 0 0.025" size="0.009" />

                        <body name="rh_lfdistal" pos="0 0 0.025">
                          <inertial mass="0.013" pos="0 0 0.0130769" quat="1 0 0 1"
                            diaginertia="1.28092e-06 1.12092e-06 5.3e-07"/>
                          <joint name="rh_LFJ1" class="middle_distal"/>
                          <geom class="plastic_visual" mesh="f_distal_pst"/>
                          <geom class="plastic_collision" type="mesh" mesh="f_distal_pst"/>
                          <site class="right_hand_touch" name="rh_T_lftip_front_left" type="box" pos="-0.00451 -0.00451 0.012" size="0.00451 0.00451 0.01905" />
                          <site class="right_hand_touch" name="rh_T_lftip_front_right" type="box" pos="0.00451 -0.00451 0.012" size="0.00451 0.00451 0.01905" />
                          <site class="right_hand_touch" name="rh_T_lftip_back_left" type="box" pos="-0.00451 0.00451 0.012" size="0.00451 0.00451 0.01905" />
                          <site class="right_hand_touch" name="rh_T_lftip_back_right" type="box" pos="0.00451 0.00451 0.012" size="0.00451 0.00451 0.01905" />
                          <site class="right_hand_touch" name="rh_T_lftip_tip" type="sphere" pos="0 0 0.024" size="0.008" />
                          <site name="site_grasp_lf1" class="site_grasp" />

                        </body>
                      </body>
                    </body>
                  </body>
                </body>
                <body name="rh_thbase" pos="0.034 -0.00858 0.029" quat="0.92388 0 0.382683 0">
                  <inertial mass="0.01" pos="0 0 0" diaginertia="1.6e-07 1.6e-07 1.6e-07"/>
                  <joint name="rh_THJ5" class="thbase"/>
                  <geom class="plastic_collision" size="0.013"/>
                  <body name="rh_thproximal">
                    <inertial mass="0.04" pos="0 0 0.019" diaginertia="1.36e-05 1.36e-05 3.13e-06"/>
                    <joint name="rh_THJ4" class="thproximal"/>
                    <geom class="plastic_visual" mesh="th_proximal"/>
                    <geom class="plastic_collision" size="0.0105 0.005" pos="0 0 0.02" type="capsule"/>
                    <site class="right_hand_touch" name="rh_T_thproximal_front_left" type="box" pos="-0.007 -0.007 0.019" size="0.007 0.007 0.032" />
                    <site class="right_hand_touch" name="rh_T_thproximal_front_right" type="box" pos="0.007 -0.007 0.019" size="0.007 0.007 0.032" />
                    <site class="right_hand_touch" name="rh_T_thproximal_back_left" type="box" pos="-0.007 0.007 0.019" size="0.007 0.007 0.032" />
                    <site class="right_hand_touch" name="rh_T_thproximal_back_right" type="box" pos="0.007 0.007 0.019" size="0.007 0.007 0.032" />
                    <site class="right_hand_touch" name="rh_T_thproximal_tip" type="sphere" pos="0 0 0.038" size="0.014" />

                    <body name="rh_thhub" pos="0 0 0.038">
                      <inertial mass="0.005" pos="0 0 0" diaginertia="1e-06 1e-06 3e-07"/>
                      <joint name="rh_THJ3" class="thhub"/>
                      <geom size="0.011" class="plastic_collision"/>
                      <body name="rh_thmiddle">
                        <inertial mass="0.02" pos="0 0 0.016" diaginertia="5.1e-06 5.1e-06 1.21e-06"/>
                        <joint name="rh_THJ2" class="thmiddle"/>
                        <geom class="plastic_visual" mesh="th_middle"/>
                        <geom size="0.009 0.005" pos="0 0 0.017" type="capsule" class="plastic_collision"/>
                        <geom size="0.01" pos="0 0 0.03" class="plastic_collision"/>
                        <site class="right_hand_touch" name="rh_T_thmiddle_front_left" type="box" pos="-0.006 -0.006 0.016" size="0.006 0.006 0.027" />
                        <site class="right_hand_touch" name="rh_T_thmiddle_front_right" type="box" pos="0.006 -0.006 0.016" size="0.006 0.006 0.027" />
                        <site class="right_hand_touch" name="rh_T_thmiddle_back_left" type="box" pos="-0.006 0.006 0.016" size="0.006 0.006 0.027" />
                        <site class="right_hand_touch" name="rh_T_thmiddle_back_right" type="box" pos="0.006 0.006 0.016" size="0.006 0.006 0.027" />
                        <site class="right_hand_touch" name="rh_T_thmiddle_tip" type="sphere" pos="0 0 0.032" size="0.012" />

                        <body name="rh_thdistal" pos="0 0 0.032" quat="1 0 0 -1">
                          <inertial mass="0.017" pos="0 0 0.0145588" quat="1 0 0 1"
                            diaginertia="2.37794e-06 2.27794e-06 1e-06"/>
                          <joint name="rh_THJ1" class="thdistal"/>
                          <geom class="plastic_visual" mesh="th_distal_pst"/>
                          <geom class="plastic_collision" type="mesh" mesh="th_distal_pst"/>
                          <site class="right_hand_touch" name="rh_T_thtip_front_left" type="box" pos="-0.0056 -0.0056 0.013" size="0.0056 0.0056 0.02218" />
                          <site class="right_hand_touch" name="rh_T_thtip_front_right" type="box" pos="0.0056 -0.0056 0.013" size="0.0056 0.0056 0.02218" />
                          <site class="right_hand_touch" name="rh_T_thtip_back_left" type="box" pos="-0.0056 0.0056 0.013" size="0.0056 0.0056 0.02218" />
                          <site class="right_hand_touch" name="rh_T_thtip_back_right" type="box" pos="0.0056 0.0056 0.013" size="0.0056 0.0056 0.02218" />
                          <site class="right_hand_touch" name="rh_T_thtip_tip" type="sphere" pos="0 0 0.026" size="0.01" />
                          <site name="site_grasp_th1" class="site_grasp" />

                        </body>
                      </body>
                    </body>
                  </body>
                </body>
              </body>
            </body>
          </body>
        </body>
    
    </body>

    <body name="desk" pos="0 0.7 -0.3">
        <geom type="box" size="0.16 0.06 0.01" rgba="0.3 0.3 0.3 1" contype="1" conaffinity="1"/>
    </body>
    <body name="joystick1" pos="-0.3 0.7 1">
      <geom name="joystick_base1" type="cylinder" size=".05 .02" rgba=".3 .3 .3 1"/>
      <body name="joystick_handle1" pos="0 0 0.02">
          <joint name="joystick_joint1" type="hinge" axis="1 0 0" damping="0.1" stiffness="0.5" range="-0.5 0.5"/>
          <geom name="joystick_stick1" type="capsule" size=".01 .04" pos="0 0 .04" rgba=".6 .6 .6 1"/>
          <geom name="joystick_knob1" type="sphere" size=".03" pos="0 0 .08" rgba=".6 .6 .6 1"/>
      </body>
    </body>
    <body name="joystick2" pos="0 0.7 1">
      <geom name="joystick_base2" type="cylinder" size=".05 .02" rgba=".3 .3 .3 1"/>
      <body name="joystick_handle2" pos="0 0 0.02">
          <joint name="joystick_joint2" type="hinge" axis="1 0 0" damping="0.1" stiffness="0.5" range="-0.5 0.5"/>
          <geom name="joystick_stick2" type="capsule" size=".01 .04" pos="0 0 .04" rgba=".6 .6 .6 1"/>
          <geom name="joystick_knob2" type="cylinder" size=".02 .03" pos="0 0 .08" rgba=".6 .6 .6 1"/>
      </body>
    </body>
    <body name="joystick3" pos="0.3 0.7 1">
      <geom name="joystick_base3" type="cylinder" size=".05 .02" rgba=".3 .3 .3 1"/>
      <body name="joystick_handle3" pos="0 0 0.02">
          <joint name="joystick_joint3" type="hinge" axis="1 0 0" damping="0.1" stiffness="0.5" range="-0.5 0.5"/>
          <geom name="joystick_stick3" type="capsule" size=".01 .04" pos="0 0 .04" rgba=".6 .6 .6 1"/>
          <geom name="joystick_knob3" type="cylinder" size=".02 .03" pos="0 0 .08" quat="1 0 1 0" rgba=".6 .6 .6 1"/>
      </body>
    </body>
  </worldbody>

  <sensor>
    <touch name="RightArm_TS_palm_b0" site="rh_T_palm_b0"></touch>
    <touch name="RightArm_TS_palm_bl" site="rh_T_palm_bl"></touch>
    <touch name="RightArm_TS_palm_bm" site="rh_T_palm_bm"></touch>
    <touch name="RightArm_TS_palm_br" site="rh_T_palm_br"></touch>
    <touch name="RightArm_TS_palm_ml" site="rh_T_palm_ml"></touch>
    <touch name="RightArm_TS_palm_mm" site="rh_T_palm_mm"></touch>
    <touch name="RightArm_TS_palm_fl" site="rh_T_palm_fl"></touch>
    <touch name="RightArm_TS_palm_fm" site="rh_T_palm_fm"></touch>
    <touch name="RightArm_TS_palm_fr" site="rh_T_palm_fr"></touch>
    
    <touch name="RightArm_TS_ffproximal_front_left_bottom" site="rh_T_ffproximal_front_left_bottom"></touch>
    <touch name="RightArm_TS_ffproximal_front_right_bottom" site="rh_T_ffproximal_front_right_bottom"></touch>
    <touch name="RightArm_TS_ffproximal_front_left_top" site="rh_T_ffproximal_front_left_top"></touch>
    <touch name="RightArm_TS_ffproximal_front_right_top" site="rh_T_ffproximal_front_right_top"></touch>
    <touch name="RightArm_TS_ffproximal_back_left" site="rh_T_ffproximal_back_left"></touch>
    <touch name="RightArm_TS_ffproximal_back_right" site="rh_T_ffproximal_back_right"></touch>
    <touch name="RightArm_TS_ffproximal_tip" site="rh_T_ffproximal_tip"></touch>
    <touch name="RightArm_TS_ffmiddle_front_left" site="rh_T_ffmiddle_front_left"></touch>
    <touch name="RightArm_TS_ffmiddle_front_right" site="rh_T_ffmiddle_front_right"></touch>
    <touch name="RightArm_TS_ffmiddle_back_left" site="rh_T_ffmiddle_back_left"></touch>
    <touch name="RightArm_TS_ffmiddle_back_right" site="rh_T_ffmiddle_back_right"></touch>
    <touch name="RightArm_TS_ffmiddle_tip" site="rh_T_ffmiddle_tip"></touch>
    <touch name="RightArm_TS_fftip_front_left" site="rh_T_fftip_front_left"></touch>
    <touch name="RightArm_TS_fftip_front_right" site="rh_T_fftip_front_right"></touch>
    <touch name="RightArm_TS_fftip_back_left" site="rh_T_fftip_back_left"></touch>
    <touch name="RightArm_TS_fftip_back_right" site="rh_T_fftip_back_right"></touch>
    <touch name="RightArm_TS_fftip_tip" site="rh_T_fftip_tip"></touch>
    <touch name="RightArm_TS_mfproximal_front_left_bottom" site="rh_T_mfproximal_front_left_bottom"></touch>
    <touch name="RightArm_TS_mfproximal_front_right_bottom" site="rh_T_mfproximal_front_right_bottom"></touch>
    <touch name="RightArm_TS_mfproximal_front_left_top" site="rh_T_mfproximal_front_left_top"></touch>
    <touch name="RightArm_TS_mfproximal_front_right_top" site="rh_T_mfproximal_front_right_top"></touch>
    <touch name="RightArm_TS_mfproximal_back_left" site="rh_T_mfproximal_back_left"></touch>
    <touch name="RightArm_TS_mfproximal_back_right" site="rh_T_mfproximal_back_right"></touch>
    <touch name="RightArm_TS_mfproximal_tip" site="rh_T_mfproximal_tip"></touch>
    <touch name="RightArm_TS_mfmiddle_front_left" site="rh_T_mfmiddle_front_left"></touch>
    <touch name="RightArm_TS_mfmiddle_front_right" site="rh_T_mfmiddle_front_right"></touch>
    <touch name="RightArm_TS_mfmiddle_back_left" site="rh_T_mfmiddle_back_left"></touch>
    <touch name="RightArm_TS_mfmiddle_back_right" site="rh_T_mfmiddle_back_right"></touch>
    <touch name="RightArm_TS_mfmiddle_tip" site="rh_T_mfmiddle_tip"></touch>
    <touch name="RightArm_TS_mftip_front_left" site="rh_T_mftip_front_left"></touch>
    <touch name="RightArm_TS_mftip_front_right" site="rh_T_mftip_front_right"></touch>
    <touch name="RightArm_TS_mftip_back_left" site="rh_T_mftip_back_left"></touch>
    <touch name="RightArm_TS_mftip_back_right" site="rh_T_mftip_back_right"></touch>
    <touch name="RightArm_TS_mftip_tip" site="rh_T_mftip_tip"></touch>
    <touch name="RightArm_TS_rfproximal_front_left_bottom" site="rh_T_rfproximal_front_left_bottom"></touch>
    <touch name="RightArm_TS_rfproximal_front_right_bottom" site="rh_T_rfproximal_front_right_bottom"></touch>
    <touch name="RightArm_TS_rfproximal_front_left_top" site="rh_T_rfproximal_front_left_top"></touch>
    <touch name="RightArm_TS_rfproximal_front_right_top" site="rh_T_rfproximal_front_right_top"></touch>
    <touch name="RightArm_TS_rfproximal_back_left" site="rh_T_rfproximal_back_left"></touch>
    <touch name="RightArm_TS_rfproximal_back_right" site="rh_T_rfproximal_back_right"></touch>
    <touch name="RightArm_TS_rfproximal_tip" site="rh_T_rfproximal_tip"></touch>
    <touch name="RightArm_TS_rfmiddle_front_left" site="rh_T_rfmiddle_front_left"></touch>
    <touch name="RightArm_TS_rfmiddle_front_right" site="rh_T_rfmiddle_front_right"></touch>
    <touch name="RightArm_TS_rfmiddle_back_left" site="rh_T_rfmiddle_back_left"></touch>
    <touch name="RightArm_TS_rfmiddle_back_right" site="rh_T_rfmiddle_back_right"></touch>
    <touch name="RightArm_TS_rfmiddle_tip" site="rh_T_rfmiddle_tip"></touch>
    <touch name="RightArm_TS_rftip_front_left" site="rh_T_rftip_front_left"></touch>
    <touch name="RightArm_TS_rftip_front_right" site="rh_T_rftip_front_right"></touch>
    <touch name="RightArm_TS_rftip_back_left" site="rh_T_rftip_back_left"></touch>
    <touch name="RightArm_TS_rftip_back_right" site="rh_T_rftip_back_right"></touch>
    <touch name="RightArm_TS_rftip_tip" site="rh_T_rftip_tip"></touch>
    <touch name="RightArm_TS_lfmetacarpal_front" site="rh_T_lfmetacarpal_front"></touch>
    <touch name="RightArm_TS_lfproximal_front_left_bottom" site="rh_T_lfproximal_front_left_bottom"></touch>
    <touch name="RightArm_TS_lfproximal_front_right_bottom" site="rh_T_lfproximal_front_right_bottom"></touch>
    <touch name="RightArm_TS_lfproximal_front_left_top" site="rh_T_lfproximal_front_left_top"></touch>
    <touch name="RightArm_TS_lfproximal_front_right_top" site="rh_T_lfproximal_front_right_top"></touch>
    <touch name="RightArm_TS_lfproximal_back_left" site="rh_T_lfproximal_back_left"></touch>
    <touch name="RightArm_TS_lfproximal_back_right" site="rh_T_lfproximal_back_right"></touch>
    <touch name="RightArm_TS_lfproximal_tip" site="rh_T_lfproximal_tip"></touch>
    <touch name="RightArm_TS_lfmiddle_front_left" site="rh_T_lfmiddle_front_left"></touch>
    <touch name="RightArm_TS_lfmiddle_front_right" site="rh_T_lfmiddle_front_right"></touch>
    <touch name="RightArm_TS_lfmiddle_back_left" site="rh_T_lfmiddle_back_left"></touch>
    <touch name="RightArm_TS_lfmiddle_back_right" site="rh_T_lfmiddle_back_right"></touch>
    <touch name="RightArm_TS_lfmiddle_tip" site="rh_T_lfmiddle_tip"></touch>
    <touch name="RightArm_TS_lftip_front_left" site="rh_T_lftip_front_left"></touch>
    <touch name="RightArm_TS_lftip_front_right" site="rh_T_lftip_front_right"></touch>
    <touch name="RightArm_TS_lftip_back_left" site="rh_T_lftip_back_left"></touch>
    <touch name="RightArm_TS_lftip_back_right" site="rh_T_lftip_back_right"></touch>
    <touch name="RightArm_TS_lftip_tip" site="rh_T_lftip_tip"></touch>
    <touch name="RightArm_TS_thproximal_front_left" site="rh_T_thproximal_front_left"></touch>
    <touch name="RightArm_TS_thproximal_front_right" site="rh_T_thproximal_front_right"></touch>
    <touch name="RightArm_TS_thproximal_back_left" site="rh_T_thproximal_back_left"></touch>
    <touch name="RightArm_TS_thproximal_back_right" site="rh_T_thproximal_back_right"></touch>
    <touch name="RightArm_TS_thproximal_tip" site="rh_T_thproximal_tip"></touch>
    <touch name="RightArm_TS_thmiddle_front_left" site="rh_T_thmiddle_front_left"></touch>
    <touch name="RightArm_TS_thmiddle_front_right" site="rh_T_thmiddle_front_right"></touch>
    <touch name="RightArm_TS_thmiddle_back_left" site="rh_T_thmiddle_back_left"></touch>
    <touch name="RightArm_TS_thmiddle_back_right" site="rh_T_thmiddle_back_right"></touch>
    <touch name="RightArm_TS_thmiddle_tip" site="rh_T_thmiddle_tip"></touch>
    <touch name="RightArm_TS_thtip_front_left" site="rh_T_thtip_front_left"></touch>
    <touch name="RightArm_TS_thtip_front_right" site="rh_T_thtip_front_right"></touch>
    <touch name="RightArm_TS_thtip_back_left" site="rh_T_thtip_back_left"></touch>
    <touch name="RightArm_TS_thtip_back_right" site="rh_T_thtip_back_right"></touch>
    <touch name="RightArm_TS_thtip_tip" site="rh_T_thtip_tip"></touch>
  </sensor>

  <tendon>
    <fixed name="rh_FFJ0">
      <joint joint="rh_FFJ2" coef="1"/>
      <joint joint="rh_FFJ1" coef="1"/>
    </fixed>
    <fixed name="rh_MFJ0">
      <joint joint="rh_MFJ2" coef="1"/>
      <joint joint="rh_MFJ1" coef="1"/>
    </fixed>
    <fixed name="rh_RFJ0">
      <joint joint="rh_RFJ2" coef="1"/>
      <joint joint="rh_RFJ1" coef="1"/>
    </fixed>
    <fixed name="rh_LFJ0">
      <joint joint="rh_LFJ2" coef="1"/>
      <joint joint="rh_LFJ1" coef="1"/>
    </fixed>
  </tendon>
  
  
  <actuator>
    <general name="shoulder_pan" joint="shoulder_pan_joint" class="shoulder_pan"/>
    <general name="shoulder_lift" joint="shoulder_lift_joint" class="shoulder_lift"/>
    <general name="shoulder_roll" joint="shoulder_roll_joint" class="shoulder_roll"/>
    <general name="elbow" joint="elbow_joint" class="elbow_j"/>
  </actuator>

  <actuator>
    <position name="rh_A_WRJ0" joint="rh_WRJ0" class="wrist_z"/>
    <position name="rh_A_WRJ2" joint="rh_WRJ2" class="wrist_y"/>
    <position name="rh_A_WRJ1" joint="rh_WRJ1" class="wrist_x"/>
    <position name="rh_A_THJ5" joint="rh_THJ5" class="thbase"/>
    <position name="rh_A_THJ4" joint="rh_THJ4" class="thproximal"/>
    <position name="rh_A_THJ3" joint="rh_THJ3" class="thhub"/>
    <position name="rh_A_THJ2" joint="rh_THJ2" class="thmiddle"/>
    <position name="rh_A_THJ1" joint="rh_THJ1" class="thdistal"/>
    <position name="rh_A_FFJ4" joint="rh_FFJ4" class="knuckle"/>
    <position name="rh_A_FFJ3" joint="rh_FFJ3" class="proximal"/>
    <position name="rh_A_FFJ0" tendon="rh_FFJ0" class="middle_distal"/>
    <position name="rh_A_MFJ4" joint="rh_MFJ4" class="knuckle"/>
    <position name="rh_A_MFJ3" joint="rh_MFJ3" class="proximal"/>
    <position name="rh_A_MFJ0" tendon="rh_MFJ0" class="middle_distal"/>
    <position name="rh_A_RFJ4" joint="rh_RFJ4" class="knuckle"/>
    <position name="rh_A_RFJ3" joint="rh_RFJ3" class="proximal"/>
    <position name="rh_A_RFJ0" tendon="rh_RFJ0" class="middle_distal"/>
    <position name="rh_A_LFJ5" joint="rh_LFJ5" class="metacarpal"/>
    <position name="rh_A_LFJ4" joint="rh_LFJ4" class="knuckle"/>
    <position name="rh_A_LFJ3" joint="rh_LFJ3" class="proximal"/>
    <position name="rh_A_LFJ0" tendon="rh_LFJ0" class="middle_distal"/>
  </actuator>

  <keyframe>
    <key name="home" qpos="-1.5708 -1.5708 1.5708 -1.5708 -1.5708 0" ctrl="-1.5708 -1.5708 1.5708 -1.5708 -1.5708 0"/>
  </keyframe>

</mujoco>
